Workbook

Sheet Input_prompt
A1: ID | B1: Actividad | C1: Score_Real_Anterior | D1: ='4_Actividades_Priorizadas'!J1 -> Capa_score | E1: ='4_Actividades_Priorizadas'!K1 -> Empleabilidad | F1: ='4_Actividades_Priorizadas'!L1 -> Facilidad
A2: ='4_Actividades_Priorizadas'!A2 -> 1 | B2: ='4_Actividades_Priorizadas'!B2 -> MCP Server Prototype | C2: =(D2*0.4)+(E2*0.4)+(F2*0.2) -> 9.2 | D2: ='4_Actividades_Priorizadas'!J2 -> 10 | E2: ='4_Actividades_Priorizadas'!K2 -> 9 | F2: ='4_Actividades_Priorizadas'!L2 -> 8
A3: ='4_Actividades_Priorizadas'!A3 -> 2 | B3: ='4_Actividades_Priorizadas'!B3 -> LangChain Academy | C3: =(D3*0.4)+(E3*0.4)+(F3*0.2) -> 9.8 | D3: ='4_Actividades_Priorizadas'!J3 -> 10 | E3: ='4_Actividades_Priorizadas'!K3 -> 10 | F3: ='4_Actividades_Priorizadas'!L3 -> 9
A4: ='4_Actividades_Priorizadas'!A4 -> 3 | B4: ='4_Actividades_Priorizadas'!B4 -> Structured Outputs Lab | C4: =(D4*0.4)+(E4*0.4)+(F4*0.2) -> 7.6 | D4: ='4_Actividades_Priorizadas'!J4 -> 7 | E4: ='4_Actividades_Priorizadas'!K4 -> 8 | F4: ='4_Actividades_Priorizadas'!L4 -> 8
A5: ='4_Actividades_Priorizadas'!A5 -> 4 | B5: ='4_Actividades_Priorizadas'!B5 -> RAG Avanzado | C5: =(D5*0.4)+(E5*0.4)+(F5*0.2) -> 9.4 | D5: ='4_Actividades_Priorizadas'!J5 -> 9 | E5: ='4_Actividades_Priorizadas'!K5 -> 10 | F5: ='4_Actividades_Priorizadas'!L5 -> 9
A6: ='4_Actividades_Priorizadas'!A6 -> 5 | B6: ='4_Actividades_Priorizadas'!B6 -> dbt Fundamentals | C6: =(D6*0.4)+(E6*0.4)+(F6*0.2) -> 8.8 | D6: ='4_Actividades_Priorizadas'!J6 -> 9 | E6: ='4_Actividades_Priorizadas'!K6 -> 8 | F6: ='4_Actividades_Priorizadas'!L6 -> 10
A7: ='4_Actividades_Priorizadas'!A7 -> 6 | B7: ='4_Actividades_Priorizadas'!B7 -> n8n Workflows | C7: =(D7*0.4)+(E7*0.4)+(F7*0.2) -> 8.6 | D7: ='4_Actividades_Priorizadas'!J7 -> 10 | E7: ='4_Actividades_Priorizadas'!K7 -> 7 | F7: ='4_Actividades_Priorizadas'!L7 -> 9
A8: ='4_Actividades_Priorizadas'!A8 -> 7 | B8: ='4_Actividades_Priorizadas'!B8 -> Observabilidad LangSmith | C8: =(D8*0.4)+(E8*0.4)+(F8*0.2) -> 8.6 | D8: ='4_Actividades_Priorizadas'!J8 -> 9 | E8: ='4_Actividades_Priorizadas'!K8 -> 9 | F8: ='4_Actividades_Priorizadas'!L8 -> 7
A9: ='4_Actividades_Priorizadas'!A9 -> 8 | B9: ='4_Actividades_Priorizadas'!B9 -> Azure DP-203 | C9: =(D9*0.4)+(E9*0.4)+(F9*0.2) -> 5.6 | D9: ='4_Actividades_Priorizadas'!J9 -> 5 | E9: ='4_Actividades_Priorizadas'!K9 -> 6 | F9: ='4_Actividades_Priorizadas'!L9 -> 6
A10: ='4_Actividades_Priorizadas'!A10 -> 9 | B10: ='4_Actividades_Priorizadas'!B10 -> GCP Professional | C10: =(D10*0.4)+(E10*0.4)+(F10*0.2) -> 5.4 | D10: ='4_Actividades_Priorizadas'!J10 -> 5 | E10: ='4_Actividades_Priorizadas'!K10 -> 6 | F10: ='4_Actividades_Priorizadas'!L10 -> 5
A11: ='4_Actividades_Priorizadas'!A11 -> 10 | B11: ='4_Actividades_Priorizadas'!B11 -> Recomendaciones LinkedIn | C11: =(D11*0.4)+(E11*0.4)+(F11*0.2) -> 7.2 | D11: ='4_Actividades_Priorizadas'!J11 -> 9 | E11: ='4_Actividades_Priorizadas'!K11 -> 4 | F11: ='4_Actividades_Priorizadas'!L11 -> 10
A12: ='4_Actividades_Priorizadas'!A12 -> 11 | B12: ='4_Actividades_Priorizadas'!B12 -> Artículo #1 MCP | C12: =(D12*0.4)+(E12*0.4)+(F12*0.2) -> 8.2 | D12: ='4_Actividades_Priorizadas'!J12 -> 10 | E12: ='4_Actividades_Priorizadas'!K12 -> 6 | F12: ='4_Actividades_Priorizadas'!L12 -> 9
A13: ='4_Actividades_Priorizadas'!A13 -> 12 | B13: ='4_Actividades_Priorizadas'!B13 -> Artículo #2 RAG | C13: =(D13*0.4)+(E13*0.4)+(F13*0.2) -> 7.8 | D13: ='4_Actividades_Priorizadas'!J13 -> 9 | E13: ='4_Actividades_Priorizadas'!K13 -> 6 | F13: ='4_Actividades_Priorizadas'!L13 -> 9
... A19: ='4_Actividades_Priorizadas'!A19 -> 18 | B19: ='4_Actividades_Priorizadas'!B19 -> Gemini for Data Scientists | C19: =(D19*0.4)+(E19*0.4)+(F19*0.2) -> 8.8 | D19: ='4_Actividades_Priorizadas'!J19 -> 9 | E19: ='4_Actividades_Priorizadas'!K19 -> 9 | F19: ='4_Actividades_Priorizadas'!L19 -> 8

Sheet Output_prompt

Sheet 0_GLOSARIO_Completo
A1: 📚 GLOSARIO COMPLETO: Fórmulas, Inputs y Funcionalidad
A3: 🗂️ PROPÓSITO DE CADA PESTAÑA
A5: Pestaña | B5: Propósito | C5: Qué hace
A6: 0_GLOSARIO | B6: Documentación completa | C6: Explica fórmulas, inputs, cómo usar herramienta
A7: 1_Panel_Control | B7: Inputs centralizados | C7: Configuras restricciones, afecta pestañas 4-8
A8: 2_Matriz_Empresarial | B8: Análisis sectores | C8: 9 áreas de negocio + tu skill match por sector
A9: 3_Inversion_IA | B9: Guía práctica | C9: Decision tree + entornos práctica €0-50
A10: 4_Actividades_Datos | B10: Base de datos | C10: 12 actividades con ROI, coste, horas + fórmulas vinculadas
A11: 5_Plan_Optimo | B11: Optimización | C11: Tabla con línea de corte para ver qué cabe en restricciones
A12: 6_Ejecucion_Temporal | B12: Milestones | C12: Hitos clave por semana (manual según priorización P4)
A13: 7_Scatter_Priorizacion | B13: Visual decisión | C13: Gráfico ROI vs Coste con líneas restricción
A14: 8_Timeline_Condensado | B14: Plan ejecutable | C14: Calendario semana a semana (Doc 1)
A16: ⚙️ INPUTS PANEL CONTROL: Qué afecta cada uno
A18: Input (Pestaña 1) | B18: Celda | C18: Afecta a | D18: Cómo afecta
A19: Salario Bruto Anual | B19: B3 | C19: P1:B5, P4:Col J | D19: Coste Hora NETO → Coste Total actividades
A20: Retención % | B20: B4 | C20: P1:B5, P4:Col J | D20: Coste Hora NETO → Coste Total actividades
A21: Horas/día | B21: B7 | C21: P1:B14, P5, P6 | D21: Horas Disponibles → capacidad total short-term
A22: Días Short-term | B22: B8 | C22: P1:B13-B14, P6 | D22: Días Efectivos → semanas totales
A23: Replanificación | B23: B9 | C23: P1:B13-B14, P5 | D23: Días Efectivos +/- → más/menos capacidad
A24: Delays | B24: B10 | C24: P1:B13-B14, P5 | D24: Días Efectivos - → penaliza capacidad
A25: Factor Urgencia | B25: B11 | C25: P4:Col K | D25: Score Final × factor → cambia priorización
A26: Presupuesto Empresa | B26: B16 | C26: P1:B18, P5 | D26: Límite económico total
A27: Presupuesto Propio | B27: B17 | C27: P1:B18, P5, P7 | D27: Línea roja scatter, filtro VERDES
A30: 🧮 FÓRMULAS CLAVE
A32: Elemento | B32: Fórmula Excel | C32: Celda
A33: Coste Hora NETO | B33: =B5*(1-B6/100)/2080 | C33: P1:B8
A34: Días Efectivos | B34: =B13+B14-B15 | C34: P1:B18
A35: Horas Disponibles | B35: =B12*B18 | C35: P1:B19
A36: Coste Total | B36: =E{row}+(D{row}*1_Panel_Control!$B$8) | C36: P4:Col I
A37: Score Final | B37: =F{row}*G{row}*1_Panel_Control!$B$16 | C37: P4:Col J
A38: ROI Score (0-5) | B38: =(@SkillMatch×0.30) + (@Diferenc.×0.25) + (@Empl.×0.20) + (@Badge×0.15) + (@Tools×0.10) | C38: P4:Col E (dato)
A39: Skill Match % | B39: =(@Proyectos×30%) + (@Stack×25%) + (@Sectorial×15%) + (@Soft×10%) + (@Certs×20%) | C39: P2 (análisis)
A42: 🤖 ALGORITMO PRIORIZACIÓN (Knapsack)
A44: PASO 1: Filtrar VERDES | B44: Solo actividades con Coste Directo ≤ Presupuesto Propio (600€)
A45: PASO 2: Calcular Score Final | B45: Score = ROI × Urgencia2026 × FactorUrgenciaGeneral (ver P4 col K)
A46: PASO 3: Ordenar descendente | B46: ⚠️ MANUAL: En P4, ordenar col K de mayor a menor (Excel no puede auto-ordenar sin VBA)
A47: PASO 4: Aplicar Knapsack | B47: Ver P5: Tabla con línea de corte que indica hasta dónde llegas con restricciones
A49: 🎯 CÓMO USAR ESTA HERRAMIENTA
A51: 1. Configura restricciones en P1 (horas/día, presupuesto, replanificación)
A52: 2. Revisa P4: columna K 'Score Final' recalcula automáticamente
...

Sheet 1_Panel_Control
A1: ROADMAP 2026 - Panel Control Centralizado
A3: 💰 CONFIGURACIÓN ECONÓMICA
A4: Salario Bruto Anual OBJETIVO (€) | B4: 70000
A5: Salario Bruto Anual (€) | B5: 44000
A6: Retención efectiva OBJETIVO (%) | B6: 30
A7: Retención efectiva (%) | B7: 23.15
D9: Salario NETO Objetivo (€) | E9: =B4*(1-B6/100) -> 49000
A10: Coste Hora NETO OBJETIVO (€/h) | B10: =B4*(1-B6/100)/2080 -> 23.557692 | D10: Salario NETO (€) | E10: =B5*(1-B7/100) -> 33814
A11: Coste Hora NETO (€/h) | B11: =B5*(1-B7/100)/2080 -> 16.256731 | D11: Incremento BRUTO objetivo (%) | E11: =(B4-B5)/B5 -> 0.59090909
A13: ⏱️ CONFIGURACIÓN TEMPORAL
A15: Horas dedicadas por día | B15: 1
A16: Días Short-term base | B16: 90
A17: Replanificación (+/- días) | B17: 0
A18: Delays acumulados (días) | B18: 0
A19: Factor Urgencia General | B19: 1
A21: → Días Efectivos | B21: =B16+B17-B18 -> 90 | D21: Valor Tiempo (€ neto) | E21: =B22*B11 -> 1463.1058
A22: → Horas Disponibles en Short term | B22: =B15*B21 -> 90
A23: Semanas en Short term | B23: =ROUNDUP(B22/7,0) -> 13
A25: 💵 PRESUPUESTO
A27: Presupuesto Empresa (€) | B27: 0
A28: Presupuesto Propio (€) | B28: 600
A29: → Total Disponible (€) | B29: =B27+B28 -> 600 | D29: RESTRICCIÓN Coste total (presupuesto + tiempo) | E29: =E21+B29 -> 2063.1058

Sheet 2_Matriz_Empresarial
A1: MATRIZ EMPRESARIAL: 9 Sectores + Skill Match
A3: Sector | B3: Pain Point | C3: Objetivo | D3: Tools IA | E3: Skill Match % | F3: Gap | G3: Oportunidad | H3: Prior.
A4: Operaciones | B4: Silos datos (PDFs, ERPs) | C4: Interop. sin migrar | D4: n8n+MCP | E4: 90 | F4: MCP impl. | G4: Muy Alta | H4: ★★★★★
A5: Customer Ops | B5: Tareas repetitivas | C5: -40% coste/ticket | D5: n8n+Intercom | E5: 85 | F5: Agents autón. | G5: Alta | H5: ★★★★★
A6: Finanzas | B6: Reporting manual | C6: Auto cierre | D6: Power BI+Python | E6: 80 | F6: Financial depth | G6: Alta | H6: ★★★★
A7: Marketing | B7: Leads fríos | C7: Hiper-personal. | D7: HubSpot+OpenAI | E7: 75 | F7: Gen content | G7: Alta | H7: ★★★★
A8: IT DevOps | B8: Deuda técnica | C8: +Velocidad dev | D8: GitHub Copilot | E8: 70 | F8: Code gen scale | G8: Media | H8: ★★★
A9: Product R&D | B9: Ciclo lento | C9: Acelerar TTM | D9: Amplitude+LLM | E9: 65 | F9: PMF analytics | G9: Media | H9: ★★★
A10: Supply Chain | B10: Visibilidad baja | C10: Optim. inventario | D10: Tableau+ML | E10: 60 | F10: Supply domain | G10: Media-Alta | H10: ★★★
A11: Legal | B11: Miles contratos | C11: -50% time | D11: RAG+Streamlit | E11: 50 | F11: Legal domain | G11: Media-Alta | H11: ★★
A12: HR Talent | B12: Onboarding lento | C12: EX fluida | D12: MS Copilot | E12: 40 | F12: HR domain | G12: Baja-Media | H12: ★★
A14: 📚 CERTIFICACIONES / FORMACIÓN POR HERRAMIENTA IA
A16: Herramienta/Stack | B16: Cert. Oficial | C16: Curso Práctico | D16: Coste | E16: Tiempo | F16: ROI Perfil
A17: MCP | B17: ❌ No oficial | C17: Anthropic docs + server | D17: 0€ | E17: 30h | F17: ⭐⭐⭐⭐⭐ CRÍTICO
A18: LangChain/Graph | B18: ❌ No oficial | C18: LangChain Academy | D18: 0€ | E18: 20h | F18: ⭐⭐⭐⭐⭐
A19: Azure OpenAI | B19: ✅ AI-102 | C19: Microsoft Learn | D19: 165€ | E19: 60h | F19: ⭐⭐⭐⭐
A20: n8n | B20: ❌ No oficial | C20: n8n Academy | D20: 0€ | E20: 10h | F20: ⭐⭐⭐⭐
A21: Power Automate | B21: ✅ PL-500 | C21: Microsoft Learn | D21: 165€ | E21: 40h | F21: ⭐⭐⭐⭐
A22: AWS Bedrock | B22: ✅ ML Specialty | C22: AWS Skillbuilder | D22: 300€ | E22: 80h | F22: ⭐⭐⭐

Sheet 3_Inversion_IA_Practica
A1: INVERSIÓN IA PRÁCTICA: Decision Tree + Entornos
A3: 🌳 DECISION TREE
A5: Problema | B5: Restricciones | C5: Stack | D5: Coste/mes | E5: Complejidad | F5: Cuándo
A6: Automatizar soporte | B6: <1K usuarios | C6: n8n + OpenAI | D6: €50-200 | E6: Baja | F6: Quick wins MVP
A7: Automatizar soporte | B7: >10K enterprise | C7: Salesforce Agent | D7: €1K-5K | E7: Media | F7: Scale
A8: Insights docs | B8: Públicos | C8: LangChain+Pinecone | D8: €100-500 | E8: Media | F8: Proto/demo
A9: Insights docs | B9: Sensibles | C9: Azure OpenAI priv | D9: €1K-5K | E9: Alta | F9: Compliance
A10: Orquestar flujos | B10: Lineales A→B | C10: n8n/Make | D10: €50-300 | E10: Baja | F10: No-code rápido
A11: Orquestar flujos | B11: Decisiones/loops | C11: LangGraph+MCP | D11: €500-2K | E11: Alta | F11: 🎯 Tu dif. 2026
A14: 💻 ENTORNOS PRÁCTICA (€0-50)
A16: Proyecto | B16: Entorno | C16: Dataset | D16: Output
A17: Structured Outputs | B17: VS Code + OpenAI $5 | C17: JSON schemas reales | D17: GitHub repo + blog
A18: RAG Avanzado | B18: Docker Qdrant + LangChain | C18: PDFs públicos (arXiv) | D18: Sistema + benchmarks
A19: MCP Server | B19: Claude Desktop gratis | C19: BigQuery sandbox | D19: Server funcional + demo
A20: n8n Workflows | B20: n8n trial 14 días | C20: Escenarios lead enrichment | D20: 3 workflows + video

Sheet 4_Actividades_Priorizadas_old
A1: ID | B1: Actividad | C1: Tipo | D1: Horas | E1: Coste | F1: Score | G1: Pre_req | H1: Probabilidad
A2: 1 | B2: MCP Server Prototype | C2: IA Práctica | D2: 30 | E2: 50 | F2: 7.5 | G2: 2 | H2: 0.8
A3: 2 | B3: LangChain Academy | C3: Formación IA | D3: 20 | E3: 0 | F3: 7.35 | G3: 0 | H3: 1
A4: 3 | B4: Structured Outputs Lab | C4: IA Práctica | D4: 15 | E4: 0 | F4: 7.2 | G4: 0 | H4: 1
A5: 4 | B5: RAG Avanzado | C5: IA Práctica | D5: 20 | E5: 50 | F5: 7.05 | G5: 2 | H5: 0.9
A6: 11 | B6: Artículo #1 MCP | C6: Visibilidad | D6: 2.5 | E6: 0 | F6: 5.25 | G6: 1 | H6: 1
A7: 12 | B7: Artículo #2 RAG | C7: Visibilidad | D7: 2.5 | E7: 0 | F7: 5.25 | G7: 4 | H7: 1
A8: 6 | B8: n8n Workflows | C8: IA Práctica | D8: 12 | E8: 20 | F8: 5.04 | G8: 0 | H8: 1
A9: 7 | B9: Observabilidad LangSmith | C9: IA Práctica | D9: 8 | E9: 0 | F9: 4.8 | G9: 0 | H9: 1
A10: 8 | B10: Azure DP-203 | C10: Certificación | D10: 80 | E10: 165 | F10: 4.5 | G10: 0 | H10: 0.5
A11: 9 | B11: GCP Professional | C11: Certificación | D11: 100 | E11: 200 | F11: 4.3 | G11: 0 | H11: 0.4
A12: 10 | B12: AI-102 Azure AI | C12: Certificación | D12: 60 | E12: 165 | F12: 4.1 | G12: 0 | H12: 0.6
A13: 5 | B13: dbt Fundamentals | C13: Certificación | D13: 16 | E13: 0 | F13: 3.8 | G13: 0 | H13: 1
A14: 13 | B14: Speaker en Meetup Local de Data/IA | C14: Networking | D14: 10 | E14: 0 | F14: 3.9 | G14: 1 | H14: 0.7

Sheet 4_Actividades_Priorizadas
A1: ID | B1: Actividad | C1: Tipo | D1: Horas | E1: Coste | F1: Pre_req | G1: Probabilidad | H1: Capa_id | I1: Capa_desc | J1: Capa_score | K1: Empleabilidad | L1: Facilidad
A2: 1 | B2: MCP Server Prototype | C2: IA Práctica | D2: 30 | E2: 50 | F2: 2 | G2: 0.8 | H2: 1 | I2: Orchestration | J2: 10 | K2: 9 | L2: 8
A3: 2 | B3: LangChain Academy | C3: Formación IA | D3: 20 | E3: 0 | F3: 0 | G3: 1 | H3: 1 | I3: Orchestration | J3: 10 | K3: 10 | L3: 9
A4: 3 | B4: Structured Outputs Lab | C4: IA Práctica | D4: 15 | E4: 0 | F4: 0 | G4: 1 | H4: 4 | I4: Models (LLMs) | J4: 7 | K4: 8 | L4: 8
A5: 4 | B5: RAG Avanzado | C5: IA Práctica | D5: 20 | E5: 50 | F5: 2 | G5: 0.9 | H5: 3 | I5: Data & Memory | J5: 9 | K5: 10 | L5: 9
A6: 5 | B6: dbt Fundamentals | C6: Certificación | D6: 15 | E6: 0 | F6: 0 | G6: 0.95 | H6: 3 | I6: Data & Memory | J6: 9 | K6: 8 | L6: 10
A7: 6 | B7: n8n Workflows | C7: IA Práctica | D7: 12 | E7: 20 | F7: 0 | G7: 1 | H7: 1 | I7: Orchestration | J7: 10 | K7: 7 | L7: 9
A8: 7 | B8: Observabilidad LangSmith | C8: IA Práctica | D8: 8 | E8: 0 | F8: 2 | G8: 0.9 | H8: 2 | I8: Governance | J8: 9 | K8: 9 | L8: 7
A9: 8 | B9: Azure DP-203 | C9: Certificación | D9: 80 | E9: 165 | F9: 0 | G9: 0.5 | H9: 5 | I9: Infrastructure | J9: 5 | K9: 6 | L9: 6
A10: 9 | B10: GCP Professional | C10: Certificación | D10: 100 | E10: 200 | F10: 0 | G10: 0.4 | H10: 5 | I10: Infrastructure | J10: 5 | K10: 6 | L10: 5
A11: 10 | B11: Recomendaciones LinkedIn | C11: Visibilidad | D11: 1 | E11: 0 | F11: 0 | G11: 1 | H11: 2 | I11: Governance | J11: 9 | K11: 4 | L11: 10
A12: 11 | B12: Artículo #1 MCP | C12: Visibilidad | D12: 3 | E12: 0 | F12: 1 | G12: 0.95 | H12: 1 | I12: Orchestration | J12: 10 | K12: 6 | L12: 9
A13: 12 | B13: Artículo #2 RAG | C13: Visibilidad | D13: 3 | E13: 0 | F13: 4 | G13: 0.95 | H13: 3 | I13: Data & Memory | J13: 9 | K13: 6 | L13: 9
... A19: 18 | B19: Gemini for Data Scientists | C19: Formación IA | D19: 12 | E19: 0 | F19: 13 | G19: 0.95 | H19: 3 | I19: Data & Memory | J19: 9 | K19: 9 | L19: 8

Sheet 5_Plan_Optimo_Knapsack
A1: PLAN ÓPTIMO: Tabla Acumulativa con Línea de Corte
A3: 📊 RESTRICCIONES ACTUALES
A5: Horas Disponibles: | B5: ='1_Panel_Control'!B22 -> 90 | D5: Presupuesto Directo: | E5: ='1_Panel_Control'!B28 -> 600
A7: ⚠️ INSTRUCCIÓN: Copia actividades VERDES desde P4 (ordenadas por Score desc) aquí
A9: 📋 TABLA ACUMULATIVA (manual)
A11: # | B11: Actividad | C11: Horas | D11: Coste € | E11: Score | F11: ∑ Horas | G11: ∑ Coste | H11: ¿Cabe? | I11: Restricción Activa
A12: 1 | B12: MCP Server | C12: 30 | D12: 50 | E12: 12.75 | F12: =C12 -> 30 | G12: =D12 -> 50 | H12: =IF(AND(F12<=$B$5,G12<=$E$5),"✅ SÍ","❌ NO") -> ✅ SÍ | I12: =IF(H12="✅ SÍ","Ninguna",IF(F12>$B$5,"⏱️ Tiempo",IF(G12>$E$5,"💰 Presupuesto","Ambas"))) -> Ninguna
A13: 2 | B13: LangChain Academy | C13: 20 | D13: 0 | E13: 11.03 | F13: =F12+C13 -> 50 | G13: =G12+D13 -> 50 | H13: =IF(AND(F13<=$B$5,G13<=$E$5),"✅ SÍ","❌ NO") -> ✅ SÍ | I13: =IF(H13="✅ SÍ","Ninguna",IF(F13>$B$5,"⏱️ Tiempo",IF(G13>$E$5,"💰 Presupuesto","Ambas"))) -> Ninguna
A14: 3 | B14: Structured Outputs | C14: 15 | D14: 0 | E14: 10.8 | F14: =F13+C14 -> 65 | G14: =G13+D14 -> 50 | H14: =IF(AND(F14<=$B$5,G14<=$E$5),"✅ SÍ","❌ NO") -> ✅ SÍ | I14: =IF(H14="✅ SÍ","Ninguna",IF(F14>$B$5,"⏱️ Tiempo",IF(G14>$E$5,"💰 Presupuesto","Ambas"))) -> Ninguna
A15: 4 | B15: RAG Avanzado | C15: 20 | D15: 50 | E15: 10.58 | F15: =F14+C15 -> 85 | G15: =G14+D15 -> 100 | H15: =IF(AND(F15<=$B$5,G15<=$E$5),"✅ SÍ","❌ NO") -> ✅ SÍ | I15: =IF(H15="✅ SÍ","Ninguna",IF(F15>$B$5,"⏱️ Tiempo",IF(G15>$E$5,"💰 Presupuesto","Ambas"))) -> Ninguna
A16: 5 | B16: n8n Workflows | C16: 12 | D16: 20 | E16: 6.05 | F16: =F15+C16 -> 97 | G16: =G15+D16 -> 120 | H16: =IF(AND(F16<=$B$5,G16<=$E$5),"✅ SÍ","❌ NO") -> ❌ NO | I16: =IF(H16="✅ SÍ","Ninguna",IF(F16>$B$5,"⏱️ Tiempo",IF(G16>$E$5,"💰 Presupuesto","Ambas"))) -> ⏱️ Tiempo
A17: 6 | B17: Observabilidad | C17: 8 | D17: 0 | E17: 5.76 | F17: =F16+C17 -> 105 | G17: =G16+D17 -> 120 | H17: =IF(AND(F17<=$B$5,G17<=$E$5),"✅ SÍ","❌ NO") -> ❌ NO | I17: =IF(H17="✅ SÍ","Ninguna",IF(F17>$B$5,"⏱️ Tiempo",IF(G17>$E$5,"💰 Presupuesto","Ambas"))) -> ⏱️ Tiempo
A18: 7 | B18: dbt Fundamentals | C18: 16 | D18: 0 | E18: 5.7 | F18: =F17+C18 -> 121 | G18: =G17+D18 -> 120 | H18: =IF(AND(F18<=$B$5,G18<=$E$5),"✅ SÍ","❌ NO") -> ❌ NO | I18: =IF(H18="✅ SÍ","Ninguna",IF(F18>$B$5,"⏱️ Tiempo",IF(G18>$E$5,"💰 Presupuesto","Ambas"))) -> ⏱️ Tiempo
A21: → LÍNEA DE CORTE: Última fila con '✅ SÍ' indica límite de tu plan

Sheet 6_Ejecucion_Temporal
A1: EJECUCIÓN TEMPORAL: Milestones Short-term
A3: ⚠️ NOTA: Actualizar manualmente según priorización final P4-P5
A5: 🎯 MILESTONES CRÍTICOS
A7: Semana | B7: Milestone | C7: Actividad | D7: Impacto
A8: S4 | B8: 🎯 Contenido público | C8: Artículo #1 MCP | D8: Posicionamiento MCP early adopter
A9: S7 | B9: 🎯 Portfolio técnico | C9: Structured Outputs | D9: GitHub + blog verificable
A10: S9 | B10: 🎯 Diferenciación RAG | C10: RAG + Artículo #2 | D10: Expertise production RAG
A11: S10 | B11: 🎯 Primera cert | C11: dbt Fundamentals | D11: Badge oficial visible
A12: S12 | B12: 🎯 Proyecto diferenciador | C12: MCP Server | D12: Demo funcional + docs
A15: 📅 MÉTRICAS TEMPORALES
A17: Semanas totales: | B17: =ROUNDUP('1_Panel_Control'!B21/7,0) -> 13
A18: Carga semanal: | B18: ='1_Panel_Control'!B15*7 -> 7

Sheet 7_Scatter_Priorizacion
A1: GRÁFICO SCATTER: ROI vs Coste Total
A3: 📊 Datos del gráfico
A5: Actividad | B5: Coste Total | C5: ROI Score | D5: Estado
A6: MCP Server Prototype | B6: ='4_Actividades_Priorizadas_old'!#REF! -> #REF! | C6: 5 | D6: Verde
A7: LangChain Academy | B7: ='4_Actividades_Priorizadas_old'!#REF! -> #REF! | C7: 4.9 | D7: Verde
A8: Structured Outputs Lab | B8: ='4_Actividades_Priorizadas_old'!#REF! -> #REF! | C8: 4.8 | D8: Verde
A9: RAG Avanzado | B9: ='4_Actividades_Priorizadas_old'!#REF! -> #REF! | C9: 4.7 | D9: Verde
A10: dbt Fundamentals | B10: ='4_Actividades_Priorizadas_old'!#REF! -> #REF! | C10: 3.8 | D10: Verde
A11: n8n Workflows | B11: ='4_Actividades_Priorizadas_old'!#REF! -> #REF! | C11: 4.2 | D11: Verde
A12: Observabilidad LangSmith | B12: ='4_Actividades_Priorizadas_old'!#REF! -> #REF! | C12: 4 | D12: Verde
A13: Azure DP-203 | B13: ='4_Actividades_Priorizadas_old'!#REF! -> #REF! | C13: 4.5 | D13: Verde
A14: GCP Professional | B14: ='4_Actividades_Priorizadas_old'!#REF! -> #REF! | C14: 4.3 | D14: Verde
A32: ℹ️ Líneas restricción: Ver líneas verticales en Excel desktop (600€ rojo, ~1,460€ naranja)

Sheet 8_Timeline_Doc1
A1: TIMELINE CONDENSADO: Plan Ejecutable Semana a Semana
A3: 📅 SHORT-TERM (90 días, Ene-Mar 2026)
A5: Semana | B5: Actividad Principal | C5: Horas | D5: Coste € | E5: Milestone
A6: S1-S4 | B6: MCP Server Prototype | C6: 30h | D6: 50€
A7: S1 | B7: + Recomendaciones LinkedIn | C7: 1h | D7: 0€
A8: S3-S5 | B8: LangChain Academy | C8: 20h | D8: 0€
A9: S4 | B9: Artículo #1: MCP Enterprise | C9: 2.5h | D9: 0€ | E9: 🎯 Primer contenido público
A10: S5-S7 | B10: Structured Outputs Lab | C10: 15h | D10: 0€
A11: S6-S9 | B11: RAG Avanzado | C11: 20h | D11: 50€
A12: S7 | E12: 🎯 Portfolio técnico GitHub
A13: S8-S10 | B13: dbt Fundamentals | C13: 16h | D13: 0€
A14: S9 | B14: Artículo #2: RAG Production | C14: 2.5h | D14: 0€ | E14: 🎯 Diferenciación RAG
A15: S10-S11 | B15: n8n Workflows | C15: 12h | D15: 20€
A16: S10 | B16: + Propuesta charlas meetups | C16: 2h | D16: 0€ | E16: 🎯 Primera certificación
A17: S11-S12 | B17: Observabilidad LangSmith | C17: 8h | D17: 0€
A18: S12 | B18: Artículo #3: Multi-Cloud ETL | C18: 3h | D18: 0€ | E18: 🎯 MCP Server completado
B19: TOTAL SHORT-TERM | C19: 132h | D19: 120€
A22: ℹ️ Timeline alimentado desde Pestaña 4 priorización + Pestaña 5 corte
A25: Actividad | B25: Inicio | C25: Duración
A26: MCP Server | B26: 1 | C26: 4
A27: LangChain | B27: 3 | C27: 3
A28: Structured Outputs | B28: 5 | C28: 3
A29: RAG Avanzado | B29: 6 | C29: 4
A30: dbt Fundamentals | B30: 8 | C30: 3
A31: n8n Workflows | B31: 10 | C31: 2
A32: Observabilidad | B32: 11 | C32: 2
